<?xml version="1.0" encoding="utf-8"?>
<!-- This URDF was automatically created by SolidWorks to URDF Exporter! Originally created by Stephen Brawner (brawner@gmail.com) 
     Commit Version: 1.6.0-4-g7f85cfe  Build Version: 1.6.7995.38578
     For more information, please see http://wiki.ros.org/sw_urdf_exporter -->
<robot
  name="Arm Full Assembly V2">
  <link
    name="base_link">
    <inertial>
      <origin
        xyz="0.00023011 0.031008 -3.2998E-05"
        rpy="0 0 0" />
      <mass
        value="1.9017" />
      <inertia
        ixx="0.0024054"
        ixy="-7.4041E-06"
        ixz="-6.4163E-05"
        iyy="0.0028552"
        iyz="9.6223E-07"
        izz="0.0019193" />
    </inertial>
    <visual>
      <origin
        xyz="0 0 0"
        rpy="0 0 0" />
      <geometry>
        <mesh
          filename="package://Arm Full Assembly V2/meshes/base_link.STL" />
      </geometry>
      <material
        name="">
        <color
          rgba="0.75294 0.75294 0.75294 1" />
      </material>
    </visual>
    <collision>
      <origin
        xyz="0 0 0"
        rpy="0 0 0" />
      <geometry>
        <mesh
          filename="package://Arm Full Assembly V2/meshes/base_link.STL" />
      </geometry>
    </collision>
  </link>
  <link
    name="link_1">
    <inertial>
      <origin
        xyz="-0.053947 -0.07688 -0.027279"
        rpy="0 0 0" />
      <mass
        value="3.4436" />
      <inertia
        ixx="0.0031674"
        ixy="-0.00020315"
        ixz="-0.00067933"
        iyy="0.0063759"
        iyz="-2.6129E-05"
        izz="0.0083632" />
    </inertial>
    <visual>
      <origin
        xyz="0 0 0"
        rpy="0 0 0" />
      <geometry>
        <mesh
          filename="package://Arm Full Assembly V2/meshes/link_1.STL" />
      </geometry>
      <material
        name="">
        <color
          rgba="0.75294 0.75294 0.75294 1" />
      </material>
    </visual>
    <collision>
      <origin
        xyz="0 0 0"
        rpy="0 0 0" />
      <geometry>
        <mesh
          filename="package://Arm Full Assembly V2/meshes/link_1.STL" />
      </geometry>
    </collision>
  </link>
  <joint
    name="Shoulder Pitch"
    type="revolute">
    <origin
      xyz="0 0 0.03935"
      rpy="-1.5708 0 -1.5708" />
    <parent
      link="base_link" />
    <child
      link="link_1" />
    <axis
      xyz="0 0 0" />
    <limit
      lower="-1.0472"
      upper="3.6652"
      effort="120"
      velocity="0" />
  </joint>
  <link
    name="link_2">
    <inertial>
      <origin
        xyz="-0.00013714 -1.087E-05 -0.00021388"
        rpy="0 0 0" />
      <mass
        value="1.5154" />
      <inertia
        ixx="0.0012977"
        ixy="1.183E-10"
        ixz="3.9452E-06"
        iyy="0.00096051"
        iyz="4.3186E-10"
        izz="0.0015105" />
    </inertial>
    <visual>
      <origin
        xyz="0 0 0"
        rpy="0 0 0" />
      <geometry>
        <mesh
          filename="package://Arm Full Assembly V2/meshes/link_2.STL" />
      </geometry>
      <material
        name="">
        <color
          rgba="0.75294 0.75294 0.75294 1" />
      </material>
    </visual>
    <collision>
      <origin
        xyz="0 0 0"
        rpy="0 0 0" />
      <geometry>
        <mesh
          filename="package://Arm Full Assembly V2/meshes/link_2.STL" />
      </geometry>
    </collision>
  </link>
  <joint
    name="Elbow Pitch"
    type="revolute">
    <origin
      xyz="-0.33465 -0.094556 -0.082595"
      rpy="0.0012834 0.12902 -3.1316" />
    <parent
      link="link_1" />
    <child
      link="link_2" />
    <axis
      xyz="0 0 0" />
    <limit
      lower="-2.79253"
      upper="1.97222"
      effort="50"
      velocity="0" />
  </joint>
  <link
    name="link_3">
    <inertial>
      <origin
        xyz="0.067519 0.021689 0.037271"
        rpy="0 0 0" />
      <mass
        value="2.0738" />
      <inertia
        ixx="0.0016286"
        ixy="-5.8925E-06"
        ixz="0.00010838"
        iyy="0.0023091"
        iyz="8.651E-06"
        izz="0.0024659" />
    </inertial>
    <visual>
      <origin
        xyz="0 0 0"
        rpy="0 0 0" />
      <geometry>
        <mesh
          filename="package://Arm Full Assembly V2/meshes/link_3.STL" />
      </geometry>
      <material
        name="">
        <color
          rgba="0.75294 0.75294 0.75294 1" />
      </material>
    </visual>
    <collision>
      <origin
        xyz="0 0 0"
        rpy="0 0 0" />
      <geometry>
        <mesh
          filename="package://Arm Full Assembly V2/meshes/link_3.STL" />
      </geometry>
    </collision>
  </link>
  <joint
    name="Elbow Roll"
    type="revolute">
    <origin
      xyz="0.0031059 -0.021237 0.040517"
      rpy="0 -0.12903 -0.0098915" />
    <parent
      link="link_2" />
    <child
      link="link_3" />
    <axis
      xyz="0 0 0" />
    <limit
      lower="-3.14159"
      upper="3.14159"
      effort="35"
      velocity="0" />
  </joint>
  <link
    name="link_4">
    <inertial>
      <origin
        xyz="0.028387 -0.14674 0.0033394"
        rpy="0 0 0" />
      <mass
        value="1.5647" />
      <inertia
        ixx="0.0012279"
        ixy="7.6533E-05"
        ixz="4.0146E-05"
        iyy="0.0024381"
        iyz="-0.00015545"
        izz="0.0026646" />
    </inertial>
    <visual>
      <origin
        xyz="0 0 0"
        rpy="0 0 0" />
      <geometry>
        <mesh
          filename="package://Arm Full Assembly V2/meshes/link_4.STL" />
      </geometry>
      <material
        name="">
        <color
          rgba="0.75294 0.75294 0.75294 1" />
      </material>
    </visual>
    <collision>
      <origin
        xyz="0 0 0"
        rpy="0 0 0" />
      <geometry>
        <mesh
          filename="package://Arm Full Assembly V2/meshes/link_4.STL" />
      </geometry>
    </collision>
  </link>
  <joint
    name="Wrist Pitch"
    type="revolute">
    <origin
      xyz="0.24203 -0.10445 0.026121"
      rpy="2.6277 0.12902 0.0099744" />
    <parent
      link="link_3" />
    <child
      link="link_4" />
    <axis
      xyz="0 0 0" />
    <limit
      lower="-2.7576"
      upper="2.6704"
      effort="45"
      velocity="0" />
  </joint>
  <link
    name="end-effector">
    <inertial>
      <origin
        xyz="0.034458 0.015301 0.020483"
        rpy="0 0 0" />
      <mass
        value="0.75097" />
      <inertia
        ixx="0.00064414"
        ixy="-3.4403E-05"
        ixz="1.4852E-05"
        iyy="0.00058012"
        iyz="-2.8503E-05"
        izz="0.0010697" />
    </inertial>
    <visual>
      <origin
        xyz="0 0 0"
        rpy="0 0 0" />
      <geometry>
        <mesh
          filename="package://Arm Full Assembly V2/meshes/end-effector.STL" />
      </geometry>
      <material
        name="">
        <color
          rgba="0.75294 0.75294 0.75294 1" />
      </material>
    </visual>
    <collision>
      <origin
        xyz="0 0 0"
        rpy="0 0 0" />
      <geometry>
        <mesh
          filename="package://Arm Full Assembly V2/meshes/end-effector.STL" />
      </geometry>
    </collision>
  </link>
  <joint
    name="Wrist Roll"
    type="continuous">
    <origin
      xyz="0.16929 -0.20704 0.0044471"
      rpy="-3.0933 -0.77939 1.4693" />
    <parent
      link="link_4" />
    <child
      link="end-effector" />
    <axis
      xyz="0 0 0" />
    <limit
      effort="3"
      velocity="0" />
  </joint>
</robot>